<?xml version="1.0"?>
<!-- created with Phobos 1.0.1 "Capricious Choutengan" -->
  <robot name="doris_head">

    <link name="head_link">
      <inertial>
        <origin xyz="0 0 0" rpy="0 0 0"/>
        <mass value="0.001"/>
        <inertia ixx="0.001" ixy="0" ixz="0" iyy="0.001" iyz="0" izz="0.001"/>
      </inertial>
      <visual name="head">
        <origin xyz="-0.02248 -0.11374 -0.02141" rpy="1.5708 0 0"/>
        <geometry>
          <mesh filename="package://doris_head_description/meshes/dae/Cube.001.dae" scale="0.001 0.001 0.001"/>
        </geometry>
        <material name="Gray_001"/>
      </visual>
    </link>

    <link name="jaw_link">
      <inertial>
        <origin xyz="0 0 0" rpy="0 0 0"/>
        <mass value="0.001"/>
        <inertia ixx="0.001" ixy="0" ixz="0" iyy="0.001" iyz="0" izz="0.001"/>
      </inertial>
      <visual name="jaw">
        <origin xyz="0.05463 0.06043 -0.08008" rpy="1.5708 0 0"/>
        <geometry>
          <mesh filename="package://doris_head_description/meshes/dae/Plane.012.dae" scale="0.001 0.001 0.001"/>
        </geometry>
        <material name="Face_000"/>
      </visual>
    </link>

    <link name="left_eye_horizontal_link">
      <inertial>
        <origin xyz="0 0 0" rpy="0 0 0"/>
        <mass value="0.001"/>
        <inertia ixx="0.001" ixy="0" ixz="0" iyy="0.001" iyz="0" izz="0.001"/>
      </inertial>
    </link>

    <link name="left_eye_vertical_link">
      <inertial>
        <origin xyz="0 0 0" rpy="0 0 0"/>
        <mass value="0.001"/>
        <inertia ixx="0.001" ixy="0" ixz="0" iyy="0.001" iyz="0" izz="0.001"/>
      </inertial>
      <visual name="left_eye">
        <origin xyz="0 0 0" rpy="-1.5708 0 0"/>
        <geometry>
          <mesh filename="package://doris_head_description/meshes/dae/Cube.002.dae" scale="0.001 0.001 0.001"/>
        </geometry>
        <material name="WHITE_003"/>
      </visual>
    </link>

    <link name="left_inferior_eyelid_link">
      <inertial>
        <origin xyz="0 0 0" rpy="0 0 0"/>
        <mass value="0.001"/>
        <inertia ixx="0.001" ixy="0" ixz="0" iyy="0.001" iyz="0" izz="0.001"/>
      </inertial>
      <visual name="left_inferior_eyelid">
        <origin xyz="0.00498 -0.01247 -0.02356" rpy="-1.56706 -0.06102 -0.06125"/>
        <geometry>
          <mesh filename="package://doris_head_description/meshes/dae/Plane.015.dae" scale="0.001 0.001 0.001"/>
        </geometry>
        <material name="Gray_001"/>
      </visual>
    </link>

    <link name="left_rotacional_eyebrow_link">
      <inertial>
        <origin xyz="0 0 0" rpy="0 0 0"/>
        <mass value="0.001"/>
        <inertia ixx="0.001" ixy="0" ixz="0" iyy="0.001" iyz="0" izz="0.001"/>
      </inertial>
      <visual name="left_eyebrow">
        <origin xyz="0 0 0" rpy="0 0 0"/>
        <geometry>
          <mesh filename="package://doris_head_description/meshes/dae/Cylinder.004.dae" scale="0.001 0.001 0.001"/>
        </geometry>
        <material name="BLACK_006"/>
      </visual>
    </link>

    <link name="left_superior_eyelid_link">
      <inertial>
        <origin xyz="0 0 0" rpy="0 0 0"/>
        <mass value="0.001"/>
        <inertia ixx="0.001" ixy="0" ixz="0" iyy="0.001" iyz="0" izz="0.001"/>
      </inertial>
      <visual name="left_superior_eyelid">
        <origin xyz="0.00551 -0.01216 -0.01543" rpy="1.5708 -0.06113 0"/>
        <geometry>
          <mesh filename="package://doris_head_description/meshes/dae/Plane.001.dae" scale="0.001 0.001 0.001"/>
        </geometry>
        <material name="Gray_001"/>
      </visual>
    </link>

    <link name="left_vertical_eyebrow_link">
      <inertial>
        <origin xyz="0 0 0" rpy="0 0 0"/>
        <mass value="0.001"/>
        <inertia ixx="0.001" ixy="0" ixz="0" iyy="0.001" iyz="0" izz="0.001"/>
      </inertial>
    </link>

    <link name="neck_link">
      <inertial>
        <origin xyz="0 0 0" rpy="0 0 0"/>
        <mass value="0.001"/>
        <inertia ixx="0.001" ixy="0" ixz="0" iyy="0.001" iyz="0" izz="0.001"/>
      </inertial>
      <visual name="neck">
        <origin xyz="0 0 0" rpy="0 0 0"/>
        <geometry>
          <mesh filename="package://doris_head_description/meshes/dae/Cube.055.dae" scale="0.01 0.01 0.01"/>
        </geometry>
      </visual>
    </link>

    <link name="right_rotacional_eyebrow_link">
      <inertial>
        <origin xyz="0 0 0" rpy="0 0 0"/>
        <mass value="0.001"/>
        <inertia ixx="0.001" ixy="0" ixz="0" iyy="0.001" iyz="0" izz="0.001"/>
      </inertial>
      <visual name="right_eyebrow">
        <origin xyz="0 0 0" rpy="0 0 0"/>
        <geometry>
          <mesh filename="package://doris_head_description/meshes/dae/Cylinder.005.dae" scale="0.001 0.001 0.001"/>
        </geometry>
        <material name="BLACK_007"/>
      </visual>
    </link>

    <link name="right_vertical_eyebrow_link">
      <inertial>
        <origin xyz="0 0 0" rpy="0 0 0"/>
        <mass value="0.001"/>
        <inertia ixx="0.001" ixy="0" ixz="0" iyy="0.001" iyz="0" izz="0.001"/>
      </inertial>
    </link>

    <link name="right_eye_horizontal_link">
      <inertial>
        <origin xyz="0 0 0" rpy="0 0 0"/>
        <mass value="0.001"/>
        <inertia ixx="0.001" ixy="0" ixz="0" iyy="0.001" iyz="0" izz="0.001"/>
      </inertial>
    </link>

    <link name="right_eye_vertical_link">
      <inertial>
        <origin xyz="0 0 0" rpy="0 0 0"/>
        <mass value="0.001"/>
        <inertia ixx="0.001" ixy="0" ixz="0" iyy="0.001" iyz="0" izz="0.001"/>
      </inertial>
      <visual name="right_eye">
        <origin xyz="0 0 0" rpy="-1.5708 0 0"/>
        <geometry>
          <mesh filename="package://doris_head_description/meshes/dae/Cube.007.dae" scale="0.001 0.001 0.001"/>
        </geometry>
        <material name="WHITE_004"/>
      </visual>
    </link>

    <link name="right_inferior_eyelid_link">
      <inertial>
        <origin xyz="0 0 0" rpy="0 0 0"/>
        <mass value="0.001"/>
        <inertia ixx="0.001" ixy="0" ixz="0" iyy="0.001" iyz="0" izz="0.001"/>
      </inertial>
      <visual name="right_inferior_eyelid">
        <origin xyz="0.0038 -0.01141 -0.01966" rpy="-1.5708 0 0"/>
        <geometry>
          <mesh filename="package://doris_head_description/meshes/dae/Plane.013.dae" scale="0.001 0.001 0.001"/>
        </geometry>
        <material name="Gray_001"/>
      </visual>
    </link>

    <link name="right_superior_eyelid_link">
      <inertial>
        <origin xyz="0 0 0" rpy="0 0 0"/>
        <mass value="0.001"/>
        <inertia ixx="0.001" ixy="0" ixz="0" iyy="0.001" iyz="0" izz="0.001"/>
      </inertial>
      <visual name="right_superior_eyelid">
        <origin xyz="0.00701 -0.01106 -0.01469" rpy="1.5708 0 0.3358"/>
        <geometry>
          <mesh filename="package://doris_head_description/meshes/dae/Plane.014.dae" scale="0.001 0.001 0.001"/>
        </geometry>
        <material name="Gray_001"/>
      </visual>
    </link>

    <link name="head_root">
      <inertial>
        <origin xyz="0 0 0" rpy="0 0 0"/>
        <mass value="0.001"/>
        <inertia ixx="0.001" ixy="0" ixz="0" iyy="0.001" iyz="0" izz="0.001"/>
      </inertial>
    </link>

    <joint name="horizontal_neck_joint" type="revolute">
      <origin xyz="0 0 0" rpy="0 0 1.5708"/>
      <parent link="head_root"/>
      <child link="neck_link"/>
      <axis xyz="0 0 1.0"/>
      <limit lower="-0.86" upper="0.86" effort="1.0" velocity="10"/>
    </joint>

    <joint name="jaw_joint" type="revolute">
      <origin xyz="0.00668 -0.10888 0.05845" rpy="0 0 0"/>
      <parent link="head_link"/>
      <child link="jaw_link"/>
      <axis xyz="0 0 1.0"/>
      <limit lower="0" upper="0.5" effort="1.0" velocity="10"/>
    </joint>

    <joint name="left_eye_horizontal_joint" type="revolute">
      <origin xyz="0.09352 -0.08739 -0.05892" rpy="1.5708 0 0"/>
      <parent link="head_link"/>
      <child link="left_eye_horizontal_link"/>
      <axis xyz="0 0 1.0"/>
      <limit lower="-0.27453" upper="0.7854" effort="1.0" velocity="10"/>
    </joint>

    <joint name="left_eye_vertical_joint" type="revolute">
      <origin xyz="0 0 0" rpy="1.5708 0 0"/>
      <parent link="left_eye_horizontal_link"/>
      <child link="left_eye_vertical_link"/>
      <axis xyz="0 0 1.0"/>
      <limit lower="-0.17453" upper="0.7854" effort="1.0" velocity="10"/>
    </joint>

    <joint name="left_inferior_eyelid_joint" type="revolute">
      <origin xyz="0.09208 -0.08718 -0.0824" rpy="-3.14159 -0.06113 0"/>
      <parent link="head_link"/>
      <child link="left_inferior_eyelid_link"/>
      <axis xyz="0 0 1.0"/>
      <limit lower="-0.17453" upper="0.7854" effort="1.0" velocity="10"/>
    </joint>

    <joint name="left_rotacional_eyebrow_joint" type="revolute">
      <origin xyz="0 0 0" rpy="2e-05 1.57091 6e-05"/>
      <parent link="left_vertical_eyebrow_link"/>
      <child link="left_rotacional_eyebrow_link"/>
      <axis xyz="0 0 1.0"/>
      <limit lower="-0.17453" upper="0.4" effort="1.0" velocity="10"/>
    </joint>

    <joint name="left_superior_eyelid_joint" type="revolute">
      <origin xyz="0.09123 -0.0871 -0.04284" rpy="0 0.06113 0"/>
      <parent link="head_link"/>
      <child link="left_superior_eyelid_link"/>
      <axis xyz="0 0 1.0"/>
      <limit lower="-0.17453" upper="0.4" effort="1.0" velocity="10"/>
    </joint>

    <joint name="left_vertical_eyebrow_joint" type="prismatic">
      <origin xyz="0.1119 -0.12427 -0.0587" rpy="1.5708 0 -0.00012"/>
      <parent link="head_link"/>
      <child link="left_vertical_eyebrow_link"/>
      <axis xyz="0 0 1.0"/>
      <limit lower="0" upper="0.02" effort="1.0" velocity="10"/>
    </joint>

    <joint name="right_rotacional_eyebrow_joint" type="revolute">
      <origin xyz="0 0 0" rpy="0 1.5708 0"/>
      <parent link="right_vertical_eyebrow_link"/>
      <child link="right_rotacional_eyebrow_link"/>
      <axis xyz="0 0 1.0"/>
      <limit lower="-0.4" upper="0.17453" effort="1.0" velocity="10"/>
    </joint>

    <joint name="right_vertical_eyebrow_joint" type="prismatic">
      <origin xyz="0.1119 -0.12289 0.01565" rpy="1.5708 0 0"/>
      <parent link="head_link"/>
      <child link="right_vertical_eyebrow_link"/>
      <axis xyz="0 0 1.0"/>
      <limit lower="0" upper="0.02" effort="1.0" velocity="10"/>
    </joint>

    <joint name="right_eye_horizontal_joint" type="revolute">
      <origin xyz="0.09352 -0.08739 0.01605" rpy="1.5708 0 0"/>
      <parent link="head_link"/>
      <child link="right_eye_horizontal_link"/>
      <axis xyz="0 0 1.0"/>
      <limit lower="-0.27453" upper="0.4" effort="1.0" velocity="10"/>
    </joint>

    <joint name="right_eye_vertical_joint" type="revolute">
      <origin xyz="0 0 0" rpy="1.5708 0 0"/>
      <parent link="right_eye_horizontal_link"/>
      <child link="right_eye_vertical_link"/>
      <axis xyz="0 0 1.0"/>
      <limit lower="-0.2" upper="0.7854" effort="1.0" velocity="10"/>
    </joint>

    <joint name="right_inferior_eyelid_joint" type="revolute">
      <origin xyz="0.09188 -0.08649 -0.00398" rpy="-3.14159 0 0"/>
      <parent link="head_link"/>
      <child link="right_inferior_eyelid_link"/>
      <axis xyz="0 0 1.0"/>
      <limit lower="-0.17" upper="0.7854" effort="1.0" velocity="10"/>
    </joint>

    <joint name="right_superior_eyelid_joint" type="revolute">
      <origin xyz="0.09073 -0.08626 0.03037" rpy="0 0 0"/>
      <parent link="head_link"/>
      <child link="right_superior_eyelid_link"/>
      <axis xyz="0 0 1.0"/>
      <limit lower="-0.4" upper="0.17" effort="1.0" velocity="10"/>
    </joint>

    <joint name="vertical_neck_joint" type="revolute">
      <origin xyz="0.02367 -0.00121 0.01929" rpy="-1.5708 0 -1.5708"/>
      <parent link="neck_link"/>
      <child link="head_link"/>
      <axis xyz="0 0 1.0"/>
      <limit lower="0" upper="0.5" effort="1.0" velocity="10"/>
    </joint>
    
    <transmission name="tran1">
    <type>transmission_interface/SimpleTransmission</type>
    <joint name="horizontal_neck_joint">
      <hardwareInterface>hardware_interface/EffortJointInterface</hardwareInterface>
    </joint>
    <actuator name="motor1">
      <hardwareInterface>hardware_interface/EffortJointInterface</hardwareInterface>
      <mechanicalReduction>1</mechanicalReduction>
    </actuator>
  </transmission>

  <transmission name="tran2">
    <type>transmission_interface/SimpleTransmission</type>
    <joint name="vertical_neck_joint">
      <hardwareInterface>hardware_interface/EffortJointInterface</hardwareInterface>
    </joint>
    <actuator name="motor2">
      <hardwareInterface>hardware_interface/EffortJointInterface</hardwareInterface>
      <mechanicalReduction>1</mechanicalReduction>
    </actuator>
  </transmission>

  <transmission name="tran3">
    <type>transmission_interface/SimpleTransmission</type>
    <joint name="jaw_joint">
      <hardwareInterface>hardware_interface/EffortJointInterface</hardwareInterface>
    </joint>
    <actuator name="motor3">
      <hardwareInterface>hardware_interface/EffortJointInterface</hardwareInterface>
      <mechanicalReduction>1</mechanicalReduction>
    </actuator>
  </transmission>

  <transmission name="tran4">
    <type>transmission_interface/SimpleTransmission</type>
    <joint name="right_vertical_eyebrow_joint">
      <hardwareInterface>hardware_interface/EffortJointInterface</hardwareInterface>
    </joint>
    <actuator name="motor4">
      <hardwareInterface>hardware_interface/EffortJointInterface</hardwareInterface>
      <mechanicalReduction>1</mechanicalReduction>
    </actuator>
  </transmission>

  <transmission name="tran5">
    <type>transmission_interface/SimpleTransmission</type>
    <joint name="left_vertical_eyebrow_joint">
      <hardwareInterface>hardware_interface/EffortJointInterface</hardwareInterface>
    </joint>
    <actuator name="motor5">
      <hardwareInterface>hardware_interface/EffortJointInterface</hardwareInterface>
      <mechanicalReduction>1</mechanicalReduction>
    </actuator>
  </transmission>

  <transmission name="tran6">
    <type>transmission_interface/SimpleTransmission</type>
    <joint name="right_rotacional_eyebrow_joint">
      <hardwareInterface>hardware_interface/EffortJointInterface</hardwareInterface>
    </joint>
    <actuator name="motor6">
      <hardwareInterface>hardware_interface/EffortJointInterface</hardwareInterface>
      <mechanicalReduction>1</mechanicalReduction>
    </actuator>
  </transmission>

  <transmission name="tran7">
    <type>transmission_interface/SimpleTransmission</type>
    <joint name="left_rotacional_eyebrow_joint">
      <hardwareInterface>hardware_interface/EffortJointInterface</hardwareInterface>
    </joint>
    <actuator name="motor7">
      <hardwareInterface>hardware_interface/EffortJointInterface</hardwareInterface>
      <mechanicalReduction>1</mechanicalReduction>
    </actuator>
  </transmission>

  <transmission name="tran8">
    <type>transmission_interface/SimpleTransmission</type>
    <joint name="right_superior_eyelid_joint">
      <hardwareInterface>hardware_interface/EffortJointInterface</hardwareInterface>
    </joint>
    <actuator name="motor8">
      <hardwareInterface>hardware_interface/EffortJointInterface</hardwareInterface>
      <mechanicalReduction>1</mechanicalReduction>
    </actuator>
  </transmission>

  <transmission name="tran9">
    <type>transmission_interface/SimpleTransmission</type>
    <joint name="left_superior_eyelid_joint">
      <hardwareInterface>hardware_interface/EffortJointInterface</hardwareInterface>
    </joint>
    <actuator name="motor9">
      <hardwareInterface>hardware_interface/EffortJointInterface</hardwareInterface>
      <mechanicalReduction>1</mechanicalReduction>
    </actuator>
  </transmission>

  <transmission name="tran10">
    <type>transmission_interface/SimpleTransmission</type>
    <joint name="right_inferior_eyelid_joint">
      <hardwareInterface>hardware_interface/EffortJointInterface</hardwareInterface>
    </joint>
    <actuator name="motor10">
      <hardwareInterface>hardware_interface/EffortJointInterface</hardwareInterface>
      <mechanicalReduction>1</mechanicalReduction>
    </actuator>
  </transmission>

  <transmission name="tran11">
    <type>transmission_interface/SimpleTransmission</type>
    <joint name="left_inferior_eyelid_joint">
      <hardwareInterface>hardware_interface/EffortJointInterface</hardwareInterface>
    </joint>
    <actuator name="motor11">
      <hardwareInterface>hardware_interface/EffortJointInterface</hardwareInterface>
      <mechanicalReduction>1</mechanicalReduction>
    </actuator>
  </transmission>

  <transmission name="tran12">
    <type>transmission_interface/SimpleTransmission</type>
    <joint name="right_eye_horizontal_joint">
      <hardwareInterface>hardware_interface/EffortJointInterface</hardwareInterface>
    </joint>
    <actuator name="motor12">
      <hardwareInterface>hardware_interface/EffortJointInterface</hardwareInterface>
      <mechanicalReduction>1</mechanicalReduction>
    </actuator>
  </transmission>

  <transmission name="tran13">
    <type>transmission_interface/SimpleTransmission</type>
    <joint name="left_eye_horizontal_joint">
      <hardwareInterface>hardware_interface/EffortJointInterface</hardwareInterface>
    </joint>
    <actuator name="motor13">
      <hardwareInterface>hardware_interface/EffortJointInterface</hardwareInterface>
      <mechanicalReduction>1</mechanicalReduction>
    </actuator>
  </transmission>

  <transmission name="tran14">
    <type>transmission_interface/SimpleTransmission</type>
    <joint name="right_eye_vertical_joint">
      <hardwareInterface>hardware_interface/EffortJointInterface</hardwareInterface>
    </joint>
    <actuator name="motor14">
      <hardwareInterface>hardware_interface/EffortJointInterface</hardwareInterface>
      <mechanicalReduction>1</mechanicalReduction>
    </actuator>
  </transmission>

  <transmission name="tran15">
    <type>transmission_interface/SimpleTransmission</type>
    <joint name="left_eye_vertical_joint">
      <hardwareInterface>hardware_interface/EffortJointInterface</hardwareInterface>
    </joint>
    <actuator name="motor15">
      <hardwareInterface>hardware_interface/EffortJointInterface</hardwareInterface>
      <mechanicalReduction>1</mechanicalReduction>
    </actuator>
  </transmission>

  <gazebo>
    <plugin name="gazebo_ros_control" filename="libgazebo_ros_control.so">
      <robotNamespace>/doris_head</robotNamespace>
    </plugin>
  </gazebo>
    
    <material name="BLACK_006">
      <color rgba="0.00291 0.00291 0.00291 1.0"/>
    </material>

    <material name="BLACK_007">
      <color rgba="0.00291 0.00291 0.00291 1.0"/>
    </material>

    <material name="Face_000">
      <color rgba="0.10651 0.09584 0.11784 1.0"/>
    </material>

    <material name="Gray_001">
      <color rgba="0.24256 0.24256 0.24256 1.0"/>
    </material>

    <material name="WHITE_003">
      <color rgba="0.64 0.64 0.64 1.0"/>
    </material>

    <material name="WHITE_004">
      <color rgba="0.64 0.64 0.64 1.0"/>
    </material>

  </robot>
