<?xml version="1.0" encoding="utf-8"?>
<!-- This URDF was automatically created by SolidWorks to URDF Exporter! Originally created by Stephen Brawner (brawner@gmail.com) 
     Commit Version: 1.6.0-1-g15f4949  Build Version: 1.6.7594.29634
     For more information, please see http://wiki.ros.org/sw_urdf_exporter -->
<robot name="patrolbot_description">
  <link name="base_link">
    <inertial>
      <origin xyz="-4.0871E-05 -1.3082E-06 0.18" rpy="0 0 0" />
      <mass value="34.858" />
      <inertia ixx="0.0080128" ixy="8.4152E-06" ixz="0.00010815" iyy="1.0005" iyz="3.4516E-06" izz="1.5171" />
    </inertial>
    <visual>
      <origin xyz="0 0 0" rpy="0 0 0" />
      <geometry>
        <mesh filename="package://patrolbot_description/meshes/hull.stl" scale="1 1 0.8"/>
      </geometry>
      <material name="">
        <color rgba="0.79216 0.81961 0.93333 1" />
      </material>
    </visual>
    <collision>
      <origin xyz="0 0 0" rpy="0 0 0" />
      <geometry>
        <mesh filename="package://patrolbot_description/meshes/hull.stl" scale="1 1 0.8"/>
      </geometry>
    </collision>
  </link>
  <link name="left_wheel_link">
    <inertial>
      <origin xyz="0.0375 -5.5511E-17 -3.3307E-16" rpy="0 0 0" />
      <mass value="2.1507" />
      <inertia ixx="0.0099942" ixy="-1.5304E-22" ixz="-9.8205E-20" iyy="0.0058914" iyz="0" izz="0.0058914" />
    </inertial>
    <visual>
      <origin xyz="0 0 -0.005" rpy="0 0 0" />
      <geometry>
        <mesh filename="package://patrolbot_description/meshes/left_wheel.stl" />
      </geometry>
      <material name="">
        <color rgba="0.79216 0.81961 0.93333 1" />
      </material>
    </visual>
    <collision>
      <origin xyz="0 0 0" rpy="0 0 0" />
      <geometry>
        <mesh filename="package://patrolbot_description/meshes/left_wheel_link.STL" />
      </geometry>
    </collision>
  </link>
  <joint name="left_wheel_joint" type="continuous">
    <origin xyz="0 0.1415 0.0495" rpy="1.5672 0 1.5708" />
    <parent link="base_link" />
    <child link="left_wheel_link" />
    <axis xyz="1 0 0" />
    <limit effort="200" velocity="6.28" />
  </joint>
  <link name="right_wheel_link">
    <inertial>
      <origin xyz="-0.00029672 -1.1102E-16 1.1102E-16" rpy="0 0 0" />
      <mass value="2.1507" />
      <inertia ixx="0.0099942" ixy="9.0771E-18" ixz="-8.6087E-18" iyy="0.0058914" iyz="0" izz="0.0058914" />
    </inertial>
    <visual>
      <origin xyz="0 0 -0.005" rpy="0 0 0" />
      <geometry>
        <mesh filename="package://patrolbot_description/meshes/right_wheel.stl" />
      </geometry>
      <material name="">
        <color rgba="0.79216 0.81961 0.93333 1" />
      </material>
    </visual>
    <collision>
      <origin xyz="0 0 0" rpy="0 0 0" />
      <geometry>
        <mesh filename="package://patrolbot_description/meshes/right_wheel_link.STL" />
      </geometry>
    </collision>
  </link>
  <joint name="right_wheel_joint" type="continuous">
    <origin xyz="0 -0.1787 0.0495" rpy="0.75508 0 1.5708" />
    <parent link="base_link" />
    <child link="right_wheel_link" />
    <axis xyz="1 0 0" />
    <limit effort="200" velocity="6.28" />
  </joint>
</robot>