<?xml version="1.0" encoding="utf-8"?>
<!-- This URDF was automatically created by SolidWorks to URDF Exporter! Originally created by Stephen Brawner (brawner@gmail.com) 
     Commit Version: 1.5.1-0-g916b5db  Build Version: 1.5.7152.31018
     For more information, please see http://wiki.ros.org/sw_urdf_exporter -->
<robot
  name="doris_arm_description">
  <link
    name="arm_base_link">
    <inertial>
      <origin
        xyz="-0.021825 -0.065106 -0.0077629"
        rpy="0 0 0" />
      <mass
        value="0.086496" />
      <inertia
        ixx="0.001"
        ixy="0"
        ixz="0"
        iyy="0.001"
        iyz="0"
        izz="0.001" />
    </inertial>
    <visual>
      <origin
        xyz="0 0 0"
        rpy="0 0 0" />
      <geometry>
        <mesh
          filename="package://doris_arm_description/meshes/arm_base_link.STL" />
      </geometry>
      <material
        name="">
        <color
          rgba="0.79216 0.81961 0.93333 1" />
      </material>
    </visual>
    <collision>
      <origin
        xyz="0 0 0"
        rpy="0 0 0" />
      <geometry>
        <mesh
          filename="package://doris_arm_description/meshes/arm_base_link.STL" />
      </geometry>
    </collision>
  </link>
  <link
    name="shoulder_link">
    <inertial>
      <origin
        xyz="1.8002E-06 0.046991 1.028E-05"
        rpy="0 0 0" />
      <mass
        value="0.18737" />
      <inertia ixx="0.001" ixy="0" ixz="0" iyy="0.001" iyz="0" izz="0.001" />
    </inertial>
    <visual>
      <origin
        xyz="0 0 0"
        rpy="0 0 0" />
      <geometry>
        <mesh
          filename="package://doris_arm_description/meshes/shoulder_link.STL" />
      </geometry>
      <material
        name="">
        <color
          rgba="0.79216 0.81961 0.93333 1" />
      </material>
    </visual>
    <collision>
      <origin
        xyz="0 0 0"
        rpy="0 0 0" />
      <geometry>
        <mesh
          filename="package://doris_arm_description/meshes/shoulder_link.STL" />
      </geometry>
    </collision>
  </link>
  <joint
    name="soulder_base_joint"
    type="continuous">
    <origin
      xyz="-0.0060974 -0.065103 0.017777"
      rpy="1.5708 0 0" />
    <parent
      link="arm_base_link" />
    <child
      link="shoulder_link" />
    <axis
      xyz="0 1 0" />
    <dynamics friction="10.0" damping="0.0" />
  </joint>
  <link
    name="forearm_link">
    <inertial>
      <origin
        xyz="-1.0864E-05 0.14596 0.0042843"
        rpy="0 0 0" />
      <mass
        value="0.073149" />
      <inertia ixx="0.001" ixy="0" ixz="0" iyy="0.001" iyz="0" izz="0.001" />
    </inertial>
    <visual>
      <origin
        xyz="0 0 0"
        rpy="0 0 0" />
      <geometry>
        <mesh
          filename="package://doris_arm_description/meshes/forearm_link.STL" />
      </geometry>
      <material
        name="">
        <color
          rgba="0.79216 0.81961 0.93333 1" />
      </material>
    </visual>
    <collision>
      <origin
        xyz="0 0 0"
        rpy="0 0 0" />
      <geometry>
        <mesh
          filename="package://doris_arm_description/meshes/forearm_link.STL" />
      </geometry>
    </collision>
  </link>
  <joint
    name="shoulder_forearm_joint"
    type="continuous">
    <origin
      xyz="0 0.0656 0"
      rpy="2.0 1.5708 0" />
    <parent
      link="shoulder_link" />
    <child
      link="forearm_link" />
    <axis
      xyz="1 0 0" />
    <dynamics friction="10.0" damping="0.0" />
  </joint>
  <link
    name="arm_link">
    <inertial>
      <origin
        xyz="6.8348E-05 -0.044602 -0.0064606"
        rpy="0 0 0" />
      <mass
        value="0.1633" />
      <inertia ixx="0.001" ixy="0" ixz="0" iyy="0.001" iyz="0" izz="0.001" />
    </inertial>
    <visual>
      <origin
        xyz="0 0 0"
        rpy="0 0 0" />
      <geometry>
        <mesh
          filename="package://doris_arm_description/meshes/arm_link.STL" />
      </geometry>
      <material
        name="">
        <color
          rgba="0.79216 0.81961 0.93333 1" />
      </material>
    </visual>
    <collision>
      <origin
        xyz="0 0 0"
        rpy="0 0 0" />
      <geometry>
        <mesh
          filename="package://doris_arm_description/meshes/arm_link.STL" />
      </geometry>
    </collision>
  </link>
  <joint
    name="arm_forearm_joint"
    type="continuous">
    <origin
      xyz="0 0.30821 -0.040455"
      rpy="1.5708 -0.74886 -1.5708" />
    <parent
      link="forearm_link" />
    <child
      link="arm_link" />
    <axis
      xyz="0 0 1" />
    <dynamics friction="10.0" damping="0.0" />
  </joint>
  <link
    name="roll_link">
    <inertial>
      <origin
        xyz="2.4999E-07 0.025907 2.5658E-07"
        rpy="0 0 0" />
      <mass
        value="0.034548" />
      <inertia ixx="0.001" ixy="0" ixz="0" iyy="0.001" iyz="0" izz="0.001" />
    </inertial>
    <visual>
      <origin
        xyz="0 0 0"
        rpy="0 0 0" />
      <geometry>
        <mesh
          filename="package://doris_arm_description/meshes/roll_link.STL" />
      </geometry>
      <material
        name="">
        <color
          rgba="0.79216 0.81961 0.93333 1" />
      </material>
    </visual>
    <collision>
      <origin
        xyz="0 0 0"
        rpy="0 0 0" />
      <geometry>
        <mesh
          filename="package://doris_arm_description/meshes/roll_link.STL" />
      </geometry>
    </collision>
  </link>
  <joint
    name="roll_arm_joint"
    type="continuous">
    <origin
      xyz="0 -0.10408 1.0864E-05"
      rpy="3.1416 -0.012731 0" />
    <parent
      link="arm_link" />
    <child
      link="roll_link" />
    <axis
      xyz="0 1 0" />
    <dynamics friction="10.0" damping="0.0" />
  </joint>
  <link
    name="yaw_link">
    <inertial>
      <origin
        xyz="4.0552E-05 -0.016021 -0.00018974"
        rpy="0 0 0" />
      <mass
        value="0.076806" />
      <inertia ixx="0.001" ixy="0" ixz="0" iyy="0.001" iyz="0" izz="0.001" />
    </inertial>
    <visual>
      <origin
        xyz="0 0 0"
        rpy="0 0 0" />
      <geometry>
        <mesh
          filename="package://doris_arm_description/meshes/yaw_link.STL" />
      </geometry>
      <material
        name="">
        <color
          rgba="0.79216 0.81961 0.93333 1" />
      </material>
    </visual>
    <collision>
      <origin
        xyz="0 0 0"
        rpy="0 0 0" />
      <geometry>
        <mesh
          filename="package://doris_arm_description/meshes/yaw_link.STL" />
      </geometry>
    </collision>
  </link>
  <joint
    name="yaw_roll_joint"
    type="continuous">
    <origin
      xyz="0 0.061919 0"
      rpy="3.1416 1.5708 0" />
    <parent
      link="roll_link" />
    <child
      link="yaw_link" />
    <axis
      xyz="0 0 1" />
    <dynamics friction="10.0" damping="0.0" />
  </joint>
  <link
    name="pitch_link">
    <inertial>
      <origin
        xyz="-0.00010854 0.0061332 0.0055683"
        rpy="0 0 0" />
      <mass
        value="0.16903" />
      <inertia ixx="0.001" ixy="0" ixz="0" iyy="0.001" iyz="0" izz="0.001" />
    </inertial>
    <visual>
      <origin
        xyz="0 0 0"
        rpy="0 0 0" />
      <geometry>
        <mesh
          filename="package://doris_arm_description/meshes/pitch_link.STL" />
      </geometry>
      <material
        name="">
        <color
          rgba="0.79216 0.81961 0.93333 1" />
      </material>
    </visual>
    <collision>
      <origin
        xyz="0 0 0"
        rpy="0 0 0" />
      <geometry>
        <mesh
          filename="package://doris_arm_description/meshes/pitch_link.STL" />
      </geometry>
    </collision>
  </link>
  <joint
    name="pitch_yaw_joint"
    type="continuous">
    <origin
      xyz="-0.007 -0.1005 -0.00015024"
      rpy="-1.4266 -1.5708 2.9857" />
    <parent
      link="yaw_link" />
    <child
      link="pitch_link" />
    <axis
      xyz="0 0 1" />
    <dynamics friction="10.0" damping="0.0" />
  </joint>
  <link
    name="gripper_left">
    <inertial>
      <origin
        xyz="-2.5501E-07 -0.0020883 0.03999"
        rpy="0 0 0" />
      <mass
        value="0.0083226" />
      <inertia ixx="0.001" ixy="0" ixz="0" iyy="0.001" iyz="0" izz="0.001" />
    </inertial>
    <visual>
      <origin
        xyz="0 0 0"
        rpy="0 0 0" />
      <geometry>
        <mesh
          filename="package://doris_arm_description/meshes/gripper_left.STL" />
      </geometry>
      <material
        name="">
        <color
          rgba="0.79216 0.81961 0.93333 1" />
      </material>
    </visual>
    <collision>
      <origin
        xyz="0 0 0"
        rpy="0 0 0" />
      <geometry>
        <mesh
          filename="package://doris_arm_description/meshes/gripper_left.STL" />
      </geometry>
    </collision>
  </link>
  <joint
    name="gripper_left_pitch"
    type="continuous">
    <origin
      xyz="0.060012 -0.007764 0.057513"
      rpy="-0.36234 0 1.5581" />
    <parent
      link="pitch_link" />
    <child
      link="gripper_left" />
    <axis
      xyz="1 0 0" />
    <dynamics friction="10.0" damping="0.0" />
  </joint>
  <link
    name="gripper_right">
    <inertial>
      <origin
        xyz="-2.5548E-07 0.012365 0.038088"
        rpy="0 0 0" />
      <mass
        value="0.0083226" />
      <inertia ixx="0.001" ixy="0" ixz="0" iyy="0.001" iyz="0" izz="0.001" />
    </inertial>
    <visual>
      <origin
        xyz="0 0 0"
        rpy="0 0 0" />
      <geometry>
        <mesh
          filename="package://doris_arm_description/meshes/gripper_right.STL" />
      </geometry>
      <material
        name="">
        <color
          rgba="0.79216 0.81961 0.93333 1" />
      </material>
    </visual>
    <collision>
      <origin
        xyz="0 0 0"
        rpy="0 0 0" />
      <geometry>
        <mesh
          filename="package://doris_arm_description/meshes/gripper_right.STL" />
      </geometry>
    </collision>
  </link>
  <joint
    name="gripper_right_pitch"
    type="continuous">
    <origin
      xyz="-0.060012 -0.006236 0.057513"
      rpy="0.0037509 0 -1.5835" />
    <parent
      link="pitch_link" />
    <child
      link="gripper_right" />
    <axis
      xyz="1 0 0" />
    <dynamics friction="10.0" damping="0.0" />
  </joint>
  <transmission name="trans_soulder_base_joint">
    <type>transmission_interface/SimpleTransmission</type>
    <joint name="soulder_base_joint">
      <hardwareInterface>hardware_interface/EffortJointInterface</hardwareInterface>
    </joint>
    <actuator name="soulder_base_joint_motor">
      <hardwareInterface>hardware_interface/EffortJointInterface</hardwareInterface>
      <mechanicalReduction>1</mechanicalReduction>
    </actuator>
  </transmission>
  <transmission name="trans_shoulder_forearm_joint">
    <type>transmission_interface/SimpleTransmission</type>
    <joint name="shoulder_forearm_joint">
      <hardwareInterface>hardware_interface/EffortJointInterface</hardwareInterface>
    </joint>
    <actuator name="shoulder_forearm_joint_motor">
      <hardwareInterface>hardware_interface/EffortJointInterface</hardwareInterface>
      <mechanicalReduction>1</mechanicalReduction>
    </actuator>
  </transmission>
  <transmission name="trans_arm_forearm_joint">
    <type>transmission_interface/SimpleTransmission</type>
    <joint name="arm_forearm_joint">
      <hardwareInterface>hardware_interface/EffortJointInterface</hardwareInterface>
    </joint>
    <actuator name="arm_forearm_joint_motor">
      <hardwareInterface>hardware_interface/EffortJointInterface</hardwareInterface>
      <mechanicalReduction>1</mechanicalReduction>
    </actuator>
  </transmission>
  <transmission name="trans_roll_arm_joint">
    <type>transmission_interface/SimpleTransmission</type>
    <joint name="roll_arm_joint">
      <hardwareInterface>hardware_interface/EffortJointInterface</hardwareInterface>
    </joint>
    <actuator name="roll_arm_joint_motor">
      <hardwareInterface>hardware_interface/EffortJointInterface</hardwareInterface>
      <mechanicalReduction>1</mechanicalReduction>
    </actuator>
  </transmission>
  <transmission name="trans_yaw_roll_joint">
    <type>transmission_interface/SimpleTransmission</type>
    <joint name="yaw_roll_joint">
      <hardwareInterface>hardware_interface/EffortJointInterface</hardwareInterface>
    </joint>
    <actuator name="yaw_roll_joint_motor">
      <hardwareInterface>hardware_interface/EffortJointInterface</hardwareInterface>
      <mechanicalReduction>1</mechanicalReduction>
    </actuator>
  </transmission>
  <transmission name="trans_pitch_yaw_joint">
    <type>transmission_interface/SimpleTransmission</type>
    <joint name="pitch_yaw_joint">
      <hardwareInterface>hardware_interface/EffortJointInterface</hardwareInterface>
    </joint>
    <actuator name="pitch_yaw_joint_motor">
      <hardwareInterface>hardware_interface/EffortJointInterface</hardwareInterface>
      <mechanicalReduction>1</mechanicalReduction>
    </actuator>
  </transmission>
  <transmission name="trans_gripper_left_pitch">
    <type>transmission_interface/SimpleTransmission</type>
    <joint name="gripper_left_pitch">
      <hardwareInterface>hardware_interface/EffortJointInterface</hardwareInterface>
    </joint>
    <actuator name="gripper_left_pitch_motor">
      <hardwareInterface>hardware_interface/EffortJointInterface</hardwareInterface>
      <mechanicalReduction>1</mechanicalReduction>
    </actuator>
  </transmission>
  <transmission name="trans_gripper_right_pitch">
    <type>transmission_interface/SimpleTransmission</type>
    <joint name="gripper_right_pitch">
      <hardwareInterface>hardware_interface/EffortJointInterface</hardwareInterface>
    </joint>
    <actuator name="gripper_right_pitch_motor">
      <hardwareInterface>hardware_interface/EffortJointInterface</hardwareInterface>
      <mechanicalReduction>1</mechanicalReduction>
    </actuator>
  </transmission>
  <gazebo>
    <plugin name="gazebo_ros_control" filename="libgazebo_ros_control.so">
      <robotNamespace>/</robotNamespace>
    </plugin>
  </gazebo>
  <gazebo reference="arm_base_link">
    <material>Gazebo/DarkGray</material>
  </gazebo>
  <gazebo reference="shoulder_link">
    <material>Gazebo/DarkGray</material>
  </gazebo>
  <gazebo reference="forearm_link">
    <material>Gazebo/DarkGray</material>
  </gazebo>
  <gazebo reference="arm_link">
    <material>Gazebo/DarkGray</material>
  </gazebo>
  <gazebo reference="roll_link">
    <material>Gazebo/DarkGray</material>
  </gazebo>
  <gazebo reference="yaw_link">
    <material>Gazebo/DarkGray</material>
  </gazebo>
  <gazebo reference="pitch_link">
    <material>Gazebo/DarkGray</material>
  </gazebo>
  <gazebo reference="gripper_left">
    <material>Gazebo/Gray</material>
  </gazebo>
  <gazebo reference="gripper_right">
    <material>Gazebo/Gray</material>
  </gazebo>
</robot>